2022-10-17 12:16:25,037 INFO    StreamThr :9080 [internal.py:wandb_internal():88] W&B internal server running at pid: 9080, started at: 2022-10-17 12:16:25.036303
2022-10-17 12:16:25,038 DEBUG   HandlerThread:9080 [handler.py:handle_request():138] handle_request: status
2022-10-17 12:16:25,040 DEBUG   SenderThread:9080 [sender.py:send_request():317] send_request: status
2022-10-17 12:16:25,041 DEBUG   SenderThread:9080 [sender.py:send():303] send: header
2022-10-17 12:16:25,041 INFO    WriterThread:9080 [datastore.py:open_for_write():75] open: .\wandb\run-20221017_121625-1pl6euch\run-1pl6euch.wandb
2022-10-17 12:16:25,041 DEBUG   SenderThread:9080 [sender.py:send():303] send: run
2022-10-17 12:16:25,043 INFO    SenderThread:9080 [sender.py:_maybe_setup_resume():593] checking resume status for raviraja/MLOps Basics/1pl6euch
2022-10-17 12:16:26,173 ERROR   SenderThread:9080 [internal_api.py:execute():216] 404 response executing GraphQL.
2022-10-17 12:16:26,173 ERROR   SenderThread:9080 [internal_api.py:execute():217] {"errors":[{"message":"project not found","path":["upsertBucket"]}],"data":{"upsertBucket":null}}
2022-10-17 12:16:27,056 INFO    WriterThread:9080 [datastore.py:close():279] close: .\wandb\run-20221017_121625-1pl6euch\run-1pl6euch.wandb
2022-10-17 12:16:27,056 INFO    HandlerThread:9080 [handler.py:finish():814] shutting down handler
2022-10-17 12:16:27,056 ERROR   StreamThr :9080 [internal.py:wandb_internal():163] Thread SenderThread:
Traceback (most recent call last):
  File "C:\Users\asabh\anaconda3\lib\site-packages\wandb\sdk\lib\retry.py", line 113, in __call__
    result = self._call_fn(*args, **kwargs)
  File "C:\Users\asabh\anaconda3\lib\site-packages\wandb\sdk\internal\internal_api.py", line 213, in execute
    return self.client.execute(*args, **kwargs)  # type: ignore
  File "C:\Users\asabh\anaconda3\lib\site-packages\wandb\vendor\gql-0.2.0\wandb_gql\client.py", line 52, in execute
    result = self._get_result(document, *args, **kwargs)
  File "C:\Users\asabh\anaconda3\lib\site-packages\wandb\vendor\gql-0.2.0\wandb_gql\client.py", line 60, in _get_result
    return self.transport.execute(document, *args, **kwargs)
  File "C:\Users\asabh\anaconda3\lib\site-packages\wandb\vendor\gql-0.2.0\wandb_gql\transport\requests.py", line 39, in execute
    request.raise_for_status()
  File "C:\Users\asabh\anaconda3\lib\site-packages\requests\models.py", line 953, in raise_for_status
    raise HTTPError(http_error_msg, response=self)
requests.exceptions.HTTPError: 404 Client Error: Not Found for url: https://api.wandb.ai/graphql

During handling of the above exception, another exception occurred:

Traceback (most recent call last):
  File "C:\Users\asabh\anaconda3\lib\site-packages\wandb\apis\normalize.py", line 26, in wrapper
    return func(*args, **kwargs)
  File "C:\Users\asabh\anaconda3\lib\site-packages\wandb\sdk\internal\internal_api.py", line 1474, in upsert_run
    response = self.gql(
  File "C:\Users\asabh\anaconda3\lib\site-packages\wandb\sdk\lib\retry.py", line 129, in __call__
    retry_timedelta_triggered = check_retry_fn(e)
  File "C:\Users\asabh\anaconda3\lib\site-packages\wandb\util.py", line 1030, in check_retry_fn
    return fallback_retry_fn(e)
  File "C:\Users\asabh\anaconda3\lib\site-packages\wandb\util.py", line 977, in no_retry_auth
    raise CommError("Permission denied, ask the project owner to grant you access")
wandb.errors.CommError: Permission denied, ask the project owner to grant you access

During handling of the above exception, another exception occurred:

Traceback (most recent call last):
  File "C:\Users\asabh\anaconda3\lib\site-packages\wandb\sdk\internal\internal_util.py", line 50, in run
    self._run()
  File "C:\Users\asabh\anaconda3\lib\site-packages\wandb\sdk\internal\internal_util.py", line 101, in _run
    self._process(record)
  File "C:\Users\asabh\anaconda3\lib\site-packages\wandb\sdk\internal\internal.py", line 308, in _process
    self._sm.send(record)
  File "C:\Users\asabh\anaconda3\lib\site-packages\wandb\sdk\internal\sender.py", line 305, in send
    send_handler(record)
  File "C:\Users\asabh\anaconda3\lib\site-packages\wandb\sdk\internal\sender.py", line 797, in send_run
    self._init_run(run, config_value_dict)
  File "C:\Users\asabh\anaconda3\lib\site-packages\wandb\sdk\internal\sender.py", line 823, in _init_run
    server_run, inserted, server_messages = self._api.upsert_run(
  File "C:\Users\asabh\anaconda3\lib\site-packages\wandb\apis\normalize.py", line 62, in wrapper
    raise CommError(message, err).with_traceback(sys.exc_info()[2])
  File "C:\Users\asabh\anaconda3\lib\site-packages\wandb\apis\normalize.py", line 26, in wrapper
    return func(*args, **kwargs)
  File "C:\Users\asabh\anaconda3\lib\site-packages\wandb\sdk\internal\internal_api.py", line 1474, in upsert_run
    response = self.gql(
  File "C:\Users\asabh\anaconda3\lib\site-packages\wandb\sdk\lib\retry.py", line 129, in __call__
    retry_timedelta_triggered = check_retry_fn(e)
  File "C:\Users\asabh\anaconda3\lib\site-packages\wandb\util.py", line 1030, in check_retry_fn
    return fallback_retry_fn(e)
  File "C:\Users\asabh\anaconda3\lib\site-packages\wandb\util.py", line 977, in no_retry_auth
    raise CommError("Permission denied, ask the project owner to grant you access")
wandb.errors.CommError: Permission denied, ask the project owner to grant you access
